<?xml version="1.0" encoding="utf-8"?>
<robot xmlns:xacro="http://www.ros.org/wiki/xacro" name="wheel">
    
  <xacro:macro name="wheel"  params="connected_to='' id:='wheel' *origin">
    <!-- Add joint -->
    <joint name="${id}_wheel_joint" type="revolute">
      <parent link="${connected_to}"/>
      <child link="${id}_wheel_link"/>
      <xacro:insert_block name="origin" />      
      <axis xyz="1 0 0"/>
      <limit effort="30" velocity="60.0"/>
    </joint>


    <link name="${id}_wheel_link">
      <inertial>
        <mass value="11"/>
        <origin xyz="0 0 0" rpy="0 0 0"/>
        <inertia ixx="0.58631238" ixy="0.0" ixz="0.0" iyy="0.33552910" iyz="0.0" izz="0.33552910"/>
      </inertial>
      <collision name="${id}_wheel_collision">
        <geometry>
          <sphere radius="0.31265"/>
        </geometry>
      </collision>
      <visual>
        <origin xyz="0 0 0" rpy="0 0 0"/>
        <geometry>
          <mesh filename="package://maila_description/urdf/components/meshes/wheel.obj" scale="0.01 0.01 0.01"/>
        </geometry>
      </visual>
    </link>    
  </xacro:macro>
</robot>